Workbook
Name Fund: #REF!
Name Scenario: #REF!

Sheet Table of Contents
A1: Workbook Table of Contents
A2: Overview of Monte Carlo Simulation Results & Task 1 (Red)
A3: Dashboard
A4: Decision Tree
A5: Task 2 (Purple)
A6: model
A7: living expenditure actually
A8: health expenditure
A9: Transport expenditure
A10: Task 3 (No Colour)
A11: Economic Scenarios
A12: fundGrowth
... A22: t4_salaryGrowthevent

Sheet Dashboard
A1: Simulations | B1: Income Y37 | C1: Expense | D1: Balance | E1: Recession | F1: Normal | G1: Boom | H1: Promotion≤45 | I1: Promotion46–59 | J1: Layoff≤45 | K1: Layoff46–59 | L1: Layoff≥60 | M1: EarlyRetire≥60 | P1: Customize Rate You can change the numbers below
A2: {=_xlfn.SEQUENCE(5000,1,1,1)} -> 1 | B2: 871310.39 | C2: 883717.72 | D2: =B2-C2 -> -12407.329 | E2: 10 | F2: 22 | G2: 3 | H2: 1 | I2: 1 | J2: 0 | K2: 1 | L2: 0 | M2: 1 | P2: Select KiwiSaver Contribution Rate | Q2: 0.1
A3: 2 | B3: 844899.45 | C3: 470982.66 | D3: =B3-C3 -> 373916.79 | E3: 24 | F3: 9 | G3: 2 | H3: 2 | I3: 0 | J3: 0 | K3: 1 | L3: 1 | M3: 1 | P3: Recession (Conservative) | R3: ='t4_Income from 30-64'!T37 -> 930999.09 | S3: Use default weights
A4: 3 | B4: 943200.01 | C4: 1101862.7 | D4: =B4-C4 -> -158662.71 | E4: 23 | F4: 10 | G4: 2 | H4: 0 | I4: 1 | J4: 1 | K4: 0 | L4: 0 | M4: 0 | P4: Input HarbourSafe Rate | Q4: 1 | R4: ='t4_Income from 30-64'!T37 -> 930999.09 | S4: Use optimized weights
A5: 4 | B5: 991101.68 | C5: 901618.92 | D5: =B5-C5 -> 89482.757 | E5: 11 | F5: 18 | G5: 6 | H5: 0 | I5: 1 | J5: 0 | K5: 1 | L5: 0 | M5: 0 | P5: Input Horizon Rate | Q5: 0
A6: 5 | B6: 903866.96 | C6: 795928.04 | D6: =B6-C6 -> 107938.92 | E6: 10 | F6: 20 | G6: 5 | H6: 1 | I6: 0 | J6: 2 | K6: 0 | L6: 0 | M6: 0 | P6: Input SkyHigh Rate | Q6: 0
A7: 6 | B7: 911373.83 | C7: 1127233.8 | D7: =B7-C7 -> -215859.93 | E7: 17 | F7: 15 | G7: 3 | H7: 1 | I7: 0 | J7: 0 | K7: 1 | L7: 0 | M7: 0 | P7: Normal (Balanced)
A8: 7 | B8: 919447.02 | C8: 594222.47 | D8: =B8-C8 -> 325224.55 | E8: 19 | F8: 11 | G8: 5 | H8: 0 | I8: 1 | J8: 0 | K8: 0 | L8: 0 | M8: 0 | P8: Input HarbourSafe Rate | Q8: 0
A9: 8 | B9: 1109723.1 | C9: 1047744.4 | D9: =B9-C9 -> 61978.674 | E9: 12 | F9: 17 | G9: 6 | H9: 0 | I9: 0 | J9: 0 | K9: 0 | L9: 0 | M9: 1 | P9: Input Horizon Rate | Q9: 0.5
A10: 9 | B10: 896328.68 | C10: 879059.66 | D10: =B10-C10 -> 17269.021 | E10: 17 | F10: 12 | G10: 6 | H10: 0 | I10: 0 | J10: 1 | K10: 1 | L10: 0 | M10: 0 | P10: Input SkyHigh Rate | Q10: 0.5
A11: 10 | B11: 951587.3 | C11: 981796.92 | D11: =B11-C11 -> -30209.623 | E11: 14 | F11: 15 | G11: 6 | H11: 1 | I11: 0 | J11: 0 | K11: 1 | L11: 0 | M11: 0 | P11: Boom (Growth)
A12: 11 | B12: 961008.39 | C12: 635148.57 | D12: =B12-C12 -> 325859.82 | E12: 7 | F12: 22 | G12: 6 | H12: 2 | I12: 0 | J12: 0 | K12: 0 | L12: 0 | M12: 0 | P12: Input HarbourSafe Rate | Q12: 0
A13: 12 | B13: 949477.55 | C13: 535794.3 | D13: =B13-C13 -> 413683.25 | E13: 20 | F13: 10 | G13: 5 | H13: 2 | I13: 0 | J13: 1 | K13: 0 | L13: 0 | M13: 1 | P13: Input Horizon Rate | Q13: 0
A14: 13 | B14: 997748.17 | C14: 1317405.9 | D14: =B14-C14 -> -319657.74 | E14: 11 | F14: 19 | G14: 5 | H14: 1 | I14: 0 | J14: 0 | K14: 1 | L14: 0 | M14: 0 | P14: Input SkyHigh Rate | Q14: 1
A15: 14 | B15: 1037184.6 | C15: 1400100.3 | D15: =B15-C15 -> -362915.72 | E15: 12 | F15: 18 | G15: 5 | H15: 1 | I15: 0 | J15: 1 | K15: 0 | L15: 0 | M15: 1
A16: 15 | B16: 920490.64 | C16: 732627.66 | D16: =B16-C16 -> 187862.98 | E16: 11 | F16: 19 | G16: 5 | H16: 1 | I16: 0 | J16: 0 | K16: 0 | L16: 0 | M16: 0
A17: 16 | B17: 931045.67 | C17: 889977.42 | D17: =B17-C17 -> 41068.248 | E17: 18 | F17: 13 | G17: 4 | H17: 1 | I17: 0 | J17: 0 | K17: 0 | L17: 0 | M17: 1
A18: 17 | B18: 888446.38 | C18: 553338.33 | D18: =B18-C18 -> 335108.05 | E18: 19 | F18: 12 | G18: 4 | H18: 1 | I18: 0 | J18: 2 | K18: 0 | L18: 0 | M18: 0
A19: 18 | B19: 934750.27 | C19: 809477.45 | D19: =B19-C19 -> 125272.82 | E19: 11 | F19: 21 | G19: 3 | H19: 0 | I19: 0 | J19: 0 | K19: 1 | L19: 0 | M19: 0
A20: 19 | B20: 904397.09 | C20: 673648.07 | D20: =B20-C20 -> 230749.02 | E20: 14 | F20: 16 | G20: 5 | H20: 0 | I20: 0 | J20: 1 | K20: 0 | L20: 0 | M20: 0
A21: 20 | B21: 908722.92 | C21: 1033424.8 | D21: =B21-C21 -> -124701.91 | E21: 19 | F21: 11 | G21: 5 | H21: 0 | I21: 0 | J21: 0 | K21: 1 | L21: 0 | M21: 0
A22: 21 | B22: 871657.11 | C22: 1140586.7 | D22: =B22-C22 -> -268929.59 | E22: 20 | F22: 7 | G22: 8 | H22: 2 | I22: 0 | J22: 2 | K22: 0 | L22: 0 | M22: 0
A23: 22 | B23: 938866.03 | C23: 758733.31 | D23: =B23-C23 -> 180132.71 | E23: 5 | F23: 27 | G23: 3 | H23: 0 | I23: 0 | J23: 1 | K23: 1 | L23: 0 | M23: 1
A24: 23 | B24: 915127.3 | C24: 1031302.5 | D24: =B24-C24 -> -116175.24 | E24: 11 | F24: 20 | G24: 4 | H24: 2 | I24: 0 | J24: 2 | K24: 0 | L24: 0 | M24: 0
A25: 24 | B25: 826181.84 | C25: 691780.89 | D25: =B25-C25 -> 134400.95 | E25: 13 | F25: 18 | G25: 4 | H25: 1 | I25: 0 | J25: 2 | K25: 0 | L25: 0 | M25: 1 | P25: Metric | Q25: Investment (B) | R25: Expenditure (C) | S25: Difference(D)
A26: 25 | B26: 858755.86 | C26: 1023123 | D26: =B26-C26 -> -164367.19 | E26: 24 | F26: 7 | G26: 4 | H26: 2 | I26: 0 | J26: 0 | K26: 2 | L26: 0 | M26: 1 | P26: Average | Q26: =AVERAGE(B2:B5001) -> 937991.04 | R26: =AVERAGE(C2:C5001) -> 948313.05 | S26: =AVERAGE(D2:D5001) -> -10322.013
A27: 26 | B27: 950510.27 | C27: 585698.78 | D27: =B27-C27 -> 364811.49 | E27: 7 | F27: 22 | G27: 6 | H27: 0 | I27: 1 | J27: 0 | K27: 0 | L27: 0 | M27: 0 | P27: Standard Deviation | Q27: =_xlfn.STDEV.P(B2:B5001) -> 64337.558 | R27: =_xlfn.STDEV.P(C2:C5001) -> 440668.1
A28: 27 | B28: 970195.86 | C28: 758460.54 | D28: =B28-C28 -> 211735.32 | E28: 8 | F28: 24 | G28: 3 | H28: 0 | I28: 1 | J28: 2 | K28: 0 | L28: 0 | M28: 1 | P28: Min | Q28: =MIN(B2:B5001) -> 753018.22 | R28: =MIN(C2:C5001) -> 265772.44
A29: 28 | B29: 908304.95 | C29: 933922.83 | D29: =B29-C29 -> -25617.884 | E29: 18 | F29: 9 | G29: 8 | H29: 1 | I29: 1 | J29: 2 | K29: 0 | L29: 0 | M29: 1 | P29: Max | Q29: =MAX(B2:B5001) -> 1210886.5 | R29: =MAX(C2:C5001) -> 14697149
A30: 29 | B30: 890267.28 | C30: 910425.44 | D30: =B30-C30 -> -20158.158 | E30: 18 | F30: 13 | G30: 4 | H30: 1 | I30: 0 | J30: 2 | K30: 0 | L30: 0 | M30: 0 | P30: 95% CI Lower | Q30: =AVERAGE(B2:B5001)-1.96*_xlfn.STDEV.P(B2:B5001)/SQRT(5000) -> 936207.69 | R30: =AVERAGE(C2:C5001)-1.96*_xlfn.STDEV.P(C2:C5001)/SQRT(1000) -> 921000.16
A31: 30 | B31: 910429.34 | C31: 1148279.4 | D31: =B31-C31 -> -237850.05 | E31: 13 | F31: 16 | G31: 6 | H31: 2 | I31: 0 | J31: 2 | K31: 0 | L31: 0 | M31: 1 | P31: 95% CI Upper | Q31: =AVERAGE(B2:B5001)+1.96*_xlfn.STDEV.P(B2:B5001)/SQRT(1000) -> 941978.72 | R31: =AVERAGE(C2:C5001)+1.96*_xlfn.STDEV.P(C2:C5001)/SQRT(1000) -> 975625.94
A32: 31 | B32: 917258.6 | C32: 896256.77 | D32: =B32-C32 -> 21001.823 | E32: 18 | F32: 14 | G32: 3 | H32: 0 | I32: 0 | J32: 0 | K32: 1 | L32: 0 | M32: 0 | P32: 2.5% Percentile | Q32: =_xlfn.PERCENTILE.INC(B2:B5001, 0.025) -> 826531.05 | R32: =_xlfn.PERCENTILE.INC(C2:C5001, 0.025) -> 484385.41
A33: 32 | B33: 831727.25 | C33: 1502660.3 | D33: =B33-C33 -> -670933.1 | E33: 15 | F33: 15 | G33: 5 | H33: 0 | I33: 2 | J33: 1 | K33: 1 | L33: 0 | M33: 0 | P33: 97.5% Percentile | Q33: =_xlfn.PERCENTILE.INC(B2:B5001, 0.975) -> 1078537.9 | R33: =_xlfn.PERCENTILE.INC(C2:C5001, 0.975) -> 1880500.9
A34: 33 | B34: 970590.67 | C34: 1032646.9 | D34: =B34-C34 -> -62056.191 | E34: 17 | F34: 12 | G34: 6 | H34: 1 | I34: 1 | J34: 1 | K34: 0 | L34: 0 | M34: 1
A35: 34 | B35: 908267.14 | C35: 974145.11 | D35: =B35-C35 -> -65877.967 | E35: 10 | F35: 19 | G35: 6 | H35: 1 | I35: 0 | J35: 1 | K35: 1 | L35: 0 | M35: 0 | P35: Negative Count (D < 0) | Q35: =COUNTIF(D2:D5001, "<0") -> 1980
A36: 35 | B36: 970295.33 | C36: 596846.43 | D36: =B36-C36 -> 373448.9 | E36: 8 | F36: 18 | G36: 9 | H36: 2 | I36: 0 | J36: 1 | K36: 1 | L36: 0 | M36: 0
A37: 36 | B37: 881242.46 | C37: 924970.48 | D37: =B37-C37 -> -43728.014 | E37: 10 | F37: 22 | G37: 3 | H37: 1 | I37: 1 | J37: 0 | K37: 0 | L37: 0 | M37: 0
A38: 37 | B38: 876691.75 | C38: 1289855.9 | D38: =B38-C38 -> -413164.18 | E38: 22 | F38: 10 | G38: 3 | H38: 2 | I38: 0 | J38: 1 | K38: 1 | L38: 0 | M38: 0
A39: 38 | B39: 896513.82 | C39: 708543.24 | D39: =B39-C39 -> 187970.58 | E39: 17 | F39: 16 | G39: 2 | H39: 0 | I39: 0 | J39: 2 | K39: 0 | L39: 0 | M39: 0 | P39: Event Type | Q39: Total Count
A40: 39 | B40: 902309.07 | C40: 893635.08 | D40: =B40-C40 -> 8673.9933 | E40: 16 | F40: 15 | G40: 4 | H40: 1 | I40: 0 | J40: 0 | K40: 2 | L40: 0 | M40: 0 | P40: Event Type | Q40: Total Count | R40: ≤45 years | S40: 46–59 years | T40: ≥60 years
...

Sheet Decision Tree
A1: Node 1 | B1: Node 2 | C1: Node 3 | D1: Node 4 | E1: Node 5 | F1: Difference | G1: PathProbability | H1: ExpectedValue | I1: BestPath
A2: Recession | B2: Conservative | C2: Early Retirement: Yes | D2: Promotion: Yes | E2: Layoff: Yes | F2: 190263 | G2: 0.05126 | H2: 9752.8814 | I2: FALSE
A3: Recession | B3: Conservative | C3: Early Retirement: Yes | D3: Promotion: Yes | E3: Layoff: No | F3: 205972 | G3: 0.015711 | H3: 3236.0261 | I3: FALSE
A4: Recession | B4: Conservative | C4: Early Retirement: Yes | D4: Promotion: No | E4: Layoff: Yes | F4: 206847 | G4: 0.021162 | H4: 4377.2962 | I4: FALSE
A5: Recession | B5: Conservative | C5: Early Retirement: Yes | D5: Promotion: No | E5: Layoff: No | F5: 207132 | G5: 0.006486 | H5: 1343.4582 | I5: FALSE
A6: Recession | B6: Conservative | C6: Early Retirement: No | D6: Promotion: Yes | E6: Layoff: Yes | F6: 197159 | G6: 0.12936 | H6: 25504.488 | I6: TRUE
A7: Recession | B7: Conservative | C7: Early Retirement: No | D7: Promotion: Yes | E7: Layoff: No | F7: 177288 | G7: 0.03965 | H7: 7029.4692 | I7: FALSE
A8: Recession | B8: Conservative | C8: Early Retirement: No | D8: Promotion: No | E8: Layoff: Yes | F8: 208423 | G8: 0.053403 | H8: 11130.413 | I8: FALSE
A9: Recession | B9: Conservative | C9: Early Retirement: No | D9: Promotion: No | E9: Layoff: No | F9: 199340 | G9: 0.016368 | H9: 3262.7971 | I9: FALSE
A10: Recession | B10: Balanced | C10: Early Retirement: Yes | D10: Promotion: Yes | E10: Layoff: Yes | F10: 161047 | G10: 0.05126 | H10: 8255.2692 | I10: FALSE
A11: Recession | B11: Balanced | C11: Early Retirement: Yes | D11: Promotion: Yes | E11: Layoff: No | F11: 186605 | G11: 0.015711 | H11: 2931.7512 | I11: FALSE
A12: Recession | B12: Balanced | C12: Early Retirement: Yes | D12: Promotion: No | E12: Layoff: Yes | F12: 190244 | G12: 0.021162 | H12: 4025.9435 | I12: FALSE
A13: Recession | B13: Balanced | C13: Early Retirement: Yes | D13: Promotion: No | E13: Layoff: No | F13: 175228 | G13: 0.006486 | H13: 1136.5288 | I13: FALSE
... A73: Boom | B73: Growth | C73: Early Retirement: No | D73: Promotion: No | E73: Layoff: No | F73: 363822 | G73: 0.016359 | H73: 5951.7641 | I73: FALSE

Sheet t4_Income from 30-64
A1: Age | B1: Salary growth rate | C1: Payroll net income before tax | D1: Payroll net income after tax | E1: KiwiSaver gross contributions (6%) | F1: Employer superannuation contribution tax (ESCT) | G1: KiwiSaver net contributions (6%)+Subsidy | H1: Economic Scenarios | I1: HarbourSafe return rate | J1: Horizon return rate | K1: SkyHigh return rate | L1: Total funds investment return rate (current weights) | M1: Net returns of Emily's KiwiSaver Investment (deduct 28% PIR) | N1: Real value of Emily;s KiwiSaver inverstment net return (per year) | O1: Total Income (funds+salary) | P1: Inflation | Q1: Deflation factor (per year) | S1: KiwiSaver net returns(deduct 28% PIR, customized contributions and fund weights) | T1: Real value of KiwiSaver returns(consider inflation and customized contributions and fund weights) | X1: KiwiSaver net returns(deduct 28% PIR, customized contributions and fund weights) | Y1: Real value of KiwiSaver returns(consider inflation and customized contributions and fund weights) | Z1: Salary growth rate (use for simulations)
A2: {=_xlfn.SEQUENCE(35,1,30,1)} -> 30 | B2: 0.035 | C2: =VLOOKUP(t4_salaryGrowthevent!B2,t4_salaryGrowthevent!B:B,1,FALSE) -> 70000 | D2: {=_xlfn.LET( _xlpm.taxable, C2, _xlpm.kiwisaver,C2*0.03, _xlpm.incomeTax, _xlfn.IFS( _xlpm.taxable <= 15600, _xlpm.taxable * 10.5%, AND(_xlpm.taxable > 15600, _xlpm.taxable <= 53500), (_xlpm.taxable - 15600) * 17.5% + 15600 * 10.5%, AND(_xlpm.taxable > 53500, _xlpm.taxable <= 78100), (_xlpm.taxable - 53500) * 30% + (53500 - 15600) * 17.5% + 15600 * 10.5%, AND(_xlpm.taxable > 78100, _xlpm.taxable <= 180000), (_xlpm.taxable - 78100) * 33% + (78100 - 53500) * 30% + (53500 - 15600) * 17.5% + 15600 * 10.5%, _xlpm.taxable > 180000, (_xlpm.taxable - 180000) * 39% + (180000 - 78100) * 33% + (78100 - 53500) * 30% + (53500 - 15600) * 17.5% + 15600 * 10.5% ), _xlpm.acc, C2 * 0.0167, _xlpm.taxable - _xlpm.incomeTax - _xlpm.acc - _xlpm.kiwisaver )} -> 53510.5 | E2: =6%*C2 -> 4200 | F2: {=C2 * 3% * _xlfn.IFS( C2 + C2 * 3% <= 18720, 10.5%, C2 + C2 * 3% <= 64200, 17.5%, C2 + C2 * 3% <= 93720, 30%, C2 + C2 * 3% <= 216000, 33%, C2 + C2 * 3% > 216000, 39% )} -> 630 | G2: =E2-F2+521.43 -> 4091.43 | H2: Normal | I2: {=_xlfn.LET( _xlpm.ε, (_xlfn.BETA.INV(RAND(), 5, 5) - 0.5) * 2, _xlpm.Scenario,H2, _xlpm.μ, _xlfn.XLOOKUP("HarbourSafe", fundGrowth!$A$2:$A$4, INDEX(fundGrowth!$B$2:$J$4,0, MATCH(_xlpm.Scenario & " μ", fundGrowth!$B$1:$J$1, 0))), _xlpm.σ, _xlfn.XLOOKUP("HarbourSafe", fundGrowth!$A$2:$A$4, INDEX(fundGrowth!$B$2:$J$4,0, MATCH(_xlpm.Scenario & " σ", fundGrowth!$B$1:$J$1, 0))), _xlpm.μ + _xlpm.σ * _xlpm.ε )} -> 0.011039737 | J2: {=_xlfn.LET( _xlpm.ε, (_xlfn.BETA.INV(RAND(), 5, 5) - 0.5) * 2, _xlpm.Scenario,H2, _xlpm.μ, _xlfn.XLOOKUP("Horizon", fundGrowth!$A$2:$A$4, INDEX(fundGrowth!$B$2:$J$4,0, MATCH(_xlpm.Scenario & " μ", fundGrowth!$B$1:$J$1, 0))), _xlpm.σ, _xlfn.XLOOKUP("Horizon", fundGrowth!$A$2:$A$4, INDEX(fundGrowth!$B$2:$J$4,0, MATCH(_xlpm.Scenario & " σ", fundGrowth!$B$1:$J$1, 0))), _xlpm.μ + _xlpm.σ * _xlpm.ε )} -> 0.060387737 | K2: {=_xlfn.LET( _xlpm.ε, (_xlfn.BETA.INV(RAND(), 5, 5) - 0.5) * 2, _xlpm.Scenario,H2, _xlpm.μ, _xlfn.XLOOKUP("SkyHigh", fundGrowth!$A$2:$A$4, INDEX(fundGrowth!$B$2:$J$4,0, MATCH(_xlpm.Scenario & " μ", fundGrowth!$B$1:$J$1, 0))), _xlpm.σ, _xlfn.XLOOKUP("SkyHigh", fundGrowth!$A$2:$A$4, INDEX(fundGrowth!$B$2:$J$4,0, MATCH(_xlpm.Scenario & " σ", fundGrowth!$B$1:$J$1, 0))), _xlpm.μ + _xlpm.σ * _xlpm.ε )} -> 0.20930115 | L2: =0.4*I2+0.3*J2+0.3*K2 -> 0.085322562 | M2: =G2*(1+L2)*(1-28%) -> 3197.1753 | N2: =M2*Q2 -> 3168.568 | O2: =N2+D2*Q2 -> 56200.273 | P2: =_xlfn.LET( _xlpm.μ, IF(RAND() < 0.001, 6% + 1.5% * _xlfn.NORM.S.INV(RAND()), _xlfn.BETA.INV(RAND(), 1.19, 1.22, 0.003, 0.04) ), _xlpm.ρ, _xlfn.BETA.INV(RAND(), 2, 2, 0.34,0.6), _xlpm.ε, MAX(0,_xlfn.NORM.S.INV(RAND())), _xlpm.μ + _xlpm.ρ * (_xlpm.μ - _xlpm.μ) + 1% * _xlpm.ε + MAX(0,_xlfn.IFS(A2=49,-_xlfn.NORM.INV(RAND(), 0.01, 0.005), A2=57,ABS(_xlfn.NORM.INV(RAND(), 0.02, 0.01)),TRUE,0)) ) -> 0.0090284707 | Q2: =1/(1+P2) -> 0.99105231 | S2: {=_xlfn.LET( _xlpm.KS_rate, $V$2 + 3%, _xlpm.ESCT_rate, 3%, _xlpm.W_HS, $V$3, _xlpm.W_HR, $V$4, _xlpm.W_SH, $V$5, _xlpm.salary, C2, _xlpm.salary_with_employer, _xlpm.salary + _xlpm.salary * _xlpm.ESCT_rate, _xlpm.esct, _xlpm.salary * _xlpm.ESCT_rate * _xlfn.IFS( _xlpm.salary_with_employer <= 18720, 10.5%, _xlpm.salary_with_employer <= 64200, 17.5%, _xlpm.salary_with_employer <= 93720, 30%, _xlpm.salary_with_employer <= 216000, 33%, _xlpm.salary_with_employer > 216000, 39% ), _xlpm.ks_contrib, _xlpm.salary * _xlpm.KS_rate - _xlpm.esct + 521.43, _xlpm.return_rate, _xlpm.W_HS * I2 + _xlpm.W_HR * J2 + _xlpm.W_SH * K2, _xlpm.net_growth, (1 + _xlpm.return_rate) * (1 - 28%), _xlpm.result, _xlpm.ks_contrib * _xlpm.net_growth, _xlpm.result )} -> 7026.1933 | T2: {=_xlfn.LET( _xlpm.KS_rate, $V$2 + 3%, _xlpm.ESCT_rate, 3%, _xlpm.W_HS, $V$3, _xlpm.W_HR, $V$4, _xlpm.W_SH, $V$5, _xlpm.salary, C2, _xlpm.salary_with_employer, _xlpm.salary + _xlpm.salary * _xlpm.ESCT_rate, _xlpm.esct, _xlpm.salary * _xlpm.ESCT_rate * _xlfn.IFS( _xlpm.salary_with_employer <= 18720, 10.5%, _xlpm.salary_with_employer <= 64200, 17.5%, _xlpm.salary_with_employer <= 93720, 30%, _xlpm.salary_with_employer <= 216000, 33%, _xlpm.salary_with_employer > 216000, 39% ), _xlpm.ks_contrib, _xlpm.salary * _xlpm.KS_rate - _xlpm.esct + 521.43, _xlpm.return_rate, _xlpm.W_HS * I2 + _xlpm.W_HR * J2 + _xlpm.W_SH * K2, _xlpm.net_growth, (1 + _xlpm.return_rate) * (1 - 28%), _xlpm.prev_value, IF(ROW()=2, 0, S1), _xlpm.base, IF(ROW()=2, _xlpm.ks_contrib, _xlpm.prev_value + _xlpm.ks_contrib ), _xlpm.current_value, _xlpm.base * _xlpm.net_growth, _xlpm.real_value, _xlpm.current_value * Q2, _xlpm.real_value )} -> 6963.3251 | U2: KiwiSaver Contribution Rate | V2: =Dashboard!Q2 -> 0.1 | X2: {=_xlfn.LET( _xlpm.KS_rate, Dashboard!$Q$2 + 3%, _xlpm.ESCT_rate, 3%, _xlpm.W_HS, _xlfn.SWITCH(H2, "Recession", Dashboard!$Q$4, "Normal", Dashboard!$Q$8, "Boom", Dashboard!$Q$12 ), _xlpm.W_HR, _xlfn.SWITCH(H2, "Recession", Dashboard!$Q$5, "Normal", Dashboard!$Q$9, "Boom", Dashboard!$Q$13 ), _xlpm.W_SH, _xlfn.SWITCH(H2, "Recession", Dashboard!$Q$6, "Normal", Dashboard!$Q$10, "Boom", Dashboard!$Q$14 ), _xlpm.salary, C2, _xlpm.salary_with_employer, _xlpm.salary + _xlpm.salary * _xlpm.ESCT_rate, _xlpm.esct, _xlpm.salary * _xlpm.ESCT_rate * _xlfn.IFS( _xlpm.salary_with_employer <= 18720, 10.5%, _xlpm.salary_with_employer <= 64200, 17.5%, _xlpm.salary_with_employer <= 93720, 30%, _xlpm.salary_with_employer <= 216000, 33%, _xlpm.salary_with_employer > 216000, 39% ), _xlpm.ks_contrib, _xlpm.salary * _xlpm.KS_rate - _xlpm.esct + 521.43, _xlpm.return_rate, _xlpm.W_HS * I2 + _xlpm.W_HR * J2 + _xlpm.W_SH * K2, _xlpm.net_growth, (1 + _xlpm.return_rate) * (1 - 28%), _xlpm.result, _xlpm.ks_contrib * _xlpm.net_growth, _xlpm.result )} -> 7346.7896 | Y2: {=_xlfn.LET( _xlpm.KS_rate, Dashboard!$Q$2 + 3%, _xlpm.ESCT_rate, 3%, _xlpm.W_HS, _xlfn.SWITCH(H2, "Recession", Dashboard!$Q$4, "Normal", Dashboard!$Q$8, "Boom", Dashboard!$Q$12 ), _xlpm.W_HR, _xlfn.SWITCH(H2, "Recession", Dashboard!$Q$5, "Normal", Dashboard!$Q$9, "Boom", Dashboard!$Q$13 ), _xlpm.W_SH, _xlfn.SWITCH(H2, "Recession", Dashboard!$Q$6, "Normal", Dashboard!$Q$10, "Boom", Dashboard!$Q$14 ), _xlpm.salary, C2, _xlpm.salary_with_employer, _xlpm.salary + _xlpm.salary * _xlpm.ESCT_rate, _xlpm.esct, _xlpm.salary * _xlpm.ESCT_rate * _xlfn.IFS( _xlpm.salary_with_employer <= 18720, 10.5%, _xlpm.salary_with_employer <= 64200, 17.5%, _xlpm.salary_with_employer <= 93720, 30%, _xlpm.salary_with_employer <= 216000, 33%, _xlpm.salary_with_employer > 216000, 39% ), _xlpm.ks_contrib, _xlpm.salary * _xlpm.KS_rate - _xlpm.esct + 521.43, _xlpm.return_rate, _xlpm.W_HS * I2 + _xlpm.W_HR * J2 + _xlpm.W_SH * K2, _xlpm.net_growth, (1 + _xlpm.return_rate) * (1 - 28%), _xlpm.prev_value, IF(ROW()=2, 0, X1), _xlpm.base, IF(ROW()=2, _xlpm.ks_contrib, _xlpm.prev_value + _xlpm.ks_contrib), _xlpm.current_value, _xlpm.base * _xlpm.net_growth, _xlpm.real_value, _xlpm.current_value * Q2, _xlpm.real_value )} -> 7281.0528 | Z2: 70000 | AG2: 0.03
A3: 31 | B3: =VLOOKUP(t4_salaryGrowthevent!J3,t4_salaryGrowthevent!J:J,1,FALSE) -> 0.03475 | C3: =VLOOKUP(t4_salaryGrowthevent!B3,t4_salaryGrowthevent!B:B,1,FALSE) -> 72432.5 | D3: {=_xlfn.LET( _xlpm.taxable, C3, _xlpm.kiwisaver,C3*0.03, _xlpm.incomeTax, _xlfn.IFS( _xlpm.taxable <= 15600, _xlpm.taxable * 10.5%, AND(_xlpm.taxable > 15600, _xlpm.taxable <= 53500), (_xlpm.taxable - 15600) * 17.5% + 15600 * 10.5%, AND(_xlpm.taxable > 53500, _xlpm.taxable <= 78100), (_xlpm.taxable - 53500) * 30% + (53500 - 15600) * 17.5% + 15600 * 10.5%, AND(_xlpm.taxable > 78100, _xlpm.taxable <= 180000), (_xlpm.taxable - 78100) * 33% + (78100 - 53500) * 30% + (53500 - 15600) * 17.5% + 15600 * 10.5%, _xlpm.taxable > 180000, (_xlpm.taxable - 180000) * 39% + (180000 - 78100) * 33% + (78100 - 53500) * 30% + (53500 - 15600) * 17.5% + 15600 * 10.5% ), _xlpm.acc, C3 * 0.0167, _xlpm.taxable - _xlpm.incomeTax - _xlpm.acc - _xlpm.kiwisaver )} -> 55099.652 | E3: =6%*C3 -> 4345.95 | F3: {=C3 * 3% * _xlfn.IFS( C3 + C3 * 3% <= 18720, 10.5%, C3 + C3 * 3% <= 64200, 17.5%, C3 + C3 * 3% <= 93720, 30%, C3 + C3 * 3% <= 216000, 33%, C3 + C3 * 3% > 216000, 39% )} -> 651.8925 | G3: =E3-F3+521.43 -> 4215.4875 | H3: {=_xlfn.IFS( H2="Boom", CHOOSE(MATCH(RAND(), {0,0.67,1}, 1), "Normal", "Recession"), H2="Normal", CHOOSE(MATCH(RAND(), {0,0.18,0.82,1}, 1), "Boom", "Normal", "Recession"), H2="Recession", CHOOSE(MATCH(RAND(), {0,0.17,0.34,1}, 1), "Boom", "Normal", "Recession") )} -> Boom | I3: {=_xlfn.LET( _xlpm.ε, (_xlfn.BETA.INV(RAND(), 5, 5) - 0.5) * 2, _xlpm.Scenario,H3, _xlpm.pre_scenario,H2, _xlpm.μ, _xlfn.XLOOKUP("HarbourSafe", fundGrowth!$A$2:$A$4, INDEX(fundGrowth!$B$2:$J$4,0, MATCH(_xlpm.Scenario & " μ", fundGrowth!$B$1:$J$1, 0))), _xlpm.σ, _xlfn.XLOOKUP("HarbourSafe", fundGrowth!$A$2:$A$4, INDEX(fundGrowth!$B$2:$J$4,0, MATCH(_xlpm.Scenario & " σ", fundGrowth!$B$1:$J$1, 0))), _xlpm.ρ, _xlfn.XLOOKUP("HarbourSafe", fundGrowth!$A$2:$A$4, INDEX(fundGrowth!$B$2:$J$4,0, MATCH(_xlpm.Scenario & " ρ", fundGrowth!$B$1:$J$1, 0))), _xlpm.μ_prev, _xlfn.XLOOKUP("HarbourSafe", fundGrowth!$A$2:$A$4, INDEX(fundGrowth!$B$2:$J$4,0, MATCH(_xlpm.pre_scenario & " μ", fundGrowth!$B$1:$J$1, 0))), _xlpm.μ + _xlpm.ρ*(I2-_xlpm.μ_prev) + _xlpm.σ * _xlpm.ε )} -> 0.038085905 | J3: {=_xlfn.LET( _xlpm.ε, (_xlfn.BETA.INV(RAND(), 5, 5) - 0.5) * 2, _xlpm.Scenario,H3, _xlpm.pre_scenario,H2, _xlpm.μ, _xlfn.XLOOKUP("Horizon", fundGrowth!$A$2:$A$4, INDEX(fundGrowth!$B$2:$J$4,0, MATCH(_xlpm.Scenario & " μ", fundGrowth!$B$1:$J$1, 0))), _xlpm.σ, _xlfn.XLOOKUP("Horizon", fundGrowth!$A$2:$A$4, INDEX(fundGrowth!$B$2:$J$4,0, MATCH(_xlpm.Scenario & " σ", fundGrowth!$B$1:$J$1, 0))), _xlpm.ρ, _xlfn.XLOOKUP("Horizon", fundGrowth!$A$2:$A$4, INDEX(fundGrowth!$B$2:$J$4,0, MATCH(_xlpm.Scenario & " ρ", fundGrowth!$B$1:$J$1, 0))), _xlpm.μ_prev, _xlfn.XLOOKUP("Horizon", fundGrowth!$A$2:$A$4, INDEX(fundGrowth!$B$2:$J$4,0, MATCH(_xlpm.pre_scenario & " μ", fundGrowth!$B$1:$J$1, 0))), _xlpm.μ + _xlpm.ρ*(MAX(J2, -0.05)-_xlpm.μ_prev) + _xlpm.σ * _xlpm.ε )} -> -0.14550929 | K3: {=_xlfn.LET( _xlpm.ε, (_xlfn.BETA.INV(RAND(), 5, 5) - 0.5) * 2, _xlpm.Scenario,H3, _xlpm.pre_scenario,H2, _xlpm.μ, _xlfn.XLOOKUP("SkyHigh", fundGrowth!$A$2:$A$4, INDEX(fundGrowth!$B$2:$J$4,0, MATCH(_xlpm.Scenario & " μ", fundGrowth!$B$1:$J$1, 0))), _xlpm.σ, _xlfn.XLOOKUP("SkyHigh", fundGrowth!$A$2:$A$4, INDEX(fundGrowth!$B$2:$J$4,0, MATCH(_xlpm.Scenario & " σ", fundGrowth!$B$1:$J$1, 0))), _xlpm.ρ, _xlfn.XLOOKUP("SkyHigh", fundGrowth!$A$2:$A$4, INDEX(fundGrowth!$B$2:$J$4,0, MATCH(_xlpm.Scenario & " ρ", fundGrowth!$B$1:$J$1, 0))), _xlpm.μ_prev, _xlfn.XLOOKUP("SkyHigh", fundGrowth!$A$2:$A$4, INDEX(fundGrowth!$B$2:$J$4,0, MATCH(_xlpm.pre_scenario & " μ", fundGrowth!$B$1:$J$1, 0))), _xlpm.μ + _xlpm.ρ*(MAX(K2, -0.07)-_xlpm.μ_prev) + _xlpm.σ * _xlpm.ε )} -> 0.2483702 | L3: =0.4*I3+0.3*J3+0.3*K3 -> 0.046092635 | M3: =(M2+G3)*(1+L3)*(1-28%) -> 5583.119 | N3: =M3*Q3 -> 5462.0687 | O3: =N3+D3*Q3 -> 59367.078 | P3: {=_xlfn.LET( _xlpm.state, H3, _xlpm.last, P2, _xlpm.μ, IF(RAND() < 0.001, 6% + 1.5% * _xlfn.NORM.S.INV(RAND()), _xlfn.BETA.INV(RAND(), 1.19, 1.22, 0.003, 0.04) ), _xlpm.ρ_min, _xlfn.IFS(_xlpm.state="Boom", 0.61, _xlpm.state="Normal", 0.34, _xlpm.state="Recession", 0.2), _xlpm.ρ_max, _xlfn.IFS(_xlpm.state="Boom", 0.8, _xlpm.state="Normal", 0.6, _xlpm.state="Recession", 0.33), _xlpm.α, _xlfn.IFS(_xlpm.state="Boom", 3, _xlpm.state="Normal", 2, _xlpm.state="Recession", 2), _xlpm.β, _xlfn.IFS(_xlpm.state="Boom", 2, _xlpm.state="Normal", 2, _xlpm.state="Recession", 3), _xlpm.ρ, _xlfn.BETA.INV(RAND(), _xlpm.α, _xlpm.β, _xlpm.ρ_min, _xlpm.ρ_max), _xlpm.ε, _xlfn.NORM.S.INV(RAND()), _xlpm.μ + _xlpm.ρ * (_xlpm.last - _xlpm.μ) + 0 * _xlpm.ε + MAX(0,_xlfn.IFS(A2=49,-_xlfn.NORM.INV(RAND(), 0.01, 0.005), A2=57,ABS(_xlfn.NORM.INV(RAND(), 0.02, 0.01)),TRUE,0)) )} -> 0.013016013 | Q3: =Q2/(1+P3) -> 0.97831851 | S3: {=_xlfn.LET( _xlpm.KS_rate, $V$2 + 3%, _xlpm.ESCT_rate, 3%, _xlpm.W_HS, $V$3, _xlpm.W_HR, $V$4, _xlpm.W_SH, $V$5, _xlpm.salary, C3, _xlpm.salary_with_employer, _xlpm.salary + _xlpm.salary * _xlpm.ESCT_rate, _xlpm.esct, _xlpm.salary * _xlpm.ESCT_rate * _xlfn.IFS( _xlpm.salary_with_employer <= 18720, 10.5%, _xlpm.salary_with_employer <= 64200, 17.5%, _xlpm.salary_with_employer <= 93720, 30%, _xlpm.salary_with_employer <= 216000, 33%, _xlpm.salary_with_employer > 216000, 39% ), _xlpm.ks_contrib, _xlpm.salary * _xlpm.KS_rate - _xlpm.esct + 521.43, _xlpm.return_rate, _xlpm.W_HS * I3 + _xlpm.W_HR * J3 + _xlpm.W_SH * K3, _xlpm.net_growth, (1 + _xlpm.return_rate) * (1 - 28%), _xlpm.prev_value, S2, _xlpm.result, (_xlpm.prev_value + _xlpm.ks_contrib) * _xlpm.net_growth, _xlpm.result )} -> 12285.948 | T3: {=_xlfn.LET( _xlpm.KS_rate, $V$2 + 3%, _xlpm.ESCT_rate, 3%, _xlpm.W_HS, $V$3, _xlpm.W_HR, $V$4, _xlpm.W_SH, $V$5, _xlpm.salary, C3, _xlpm.salary_with_employer, _xlpm.salary + _xlpm.salary * _xlpm.ESCT_rate, _xlpm.esct, _xlpm.salary * _xlpm.ESCT_rate * _xlfn.IFS( _xlpm.salary_with_employer <= 18720, 10.5%, _xlpm.salary_with_employer <= 64200, 17.5%, _xlpm.salary_with_employer <= 93720, 30%, _xlpm.salary_with_employer <= 216000, 33%, _xlpm.salary_with_employer > 216000, 39% ), _xlpm.ks_contrib, _xlpm.salary * _xlpm.KS_rate - _xlpm.esct + 521.43, _xlpm.return_rate, _xlpm.W_HS * I3 + _xlpm.W_HR * J3 + _xlpm.W_SH * K3, _xlpm.net_growth, (1 + _xlpm.return_rate) * (1 - 28%), _xlpm.prev_value, IF(ROW()=2, 0, S2), _xlpm.base, IF(ROW()=2, _xlpm.ks_contrib, _xlpm.prev_value + _xlpm.ks_contrib ), _xlpm.current_value, _xlpm.base * _xlpm.net_growth, _xlpm.real_value, _xlpm.current_value * Q3, _xlpm.real_value )} -> 12019.57 | U3: HarbourSafe Rate | V3: 0.4 | X3: {=_xlfn.LET( _xlpm.KS_rate, Dashboard!$Q$2 + 3%, _xlpm.ESCT_rate, 3%, _xlpm.W_HS, _xlfn.SWITCH(H2, "Recession", Dashboard!$Q$4, "Normal", Dashboard!$Q$8, "Boom", Dashboard!$Q$12 ), _xlpm.W_HR, _xlfn.SWITCH(H2, "Recession", Dashboard!$Q$5, "Normal", Dashboard!$Q$9, "Boom", Dashboard!$Q$13 ), _xlpm.W_SH, _xlfn.SWITCH(H2, "Recession", Dashboard!$Q$6, "Normal", Dashboard!$Q$10, "Boom", Dashboard!$Q$14 ), _xlpm.salary, C3, _xlpm.salary_with_employer, _xlpm.salary + _xlpm.salary * _xlpm.ESCT_rate, _xlpm.esct, _xlpm.salary * _xlpm.ESCT_rate * _xlfn.IFS( _xlpm.salary_with_employer <= 18720, 10.5%, _xlpm.salary_with_employer <= 64200, 17.5%, _xlpm.salary_with_employer <= 93720, 30%, _xlpm.salary_with_employer <= 216000, 33%, _xlpm.salary_with_employer > 216000, 39% ), _xlpm.ks_contrib, _xlpm.salary * _xlpm.KS_rate - _xlpm.esct + 521.43, _xlpm.return_rate, _xlpm.W_HS * I3 + _xlpm.W_HR * J3 + _xlpm.W_SH * K3, _xlpm.net_growth, (1 + _xlpm.return_rate) * (1 - 28%), _xlpm.prev_value, S2, _xlpm.result, (_xlpm.prev_value + _xlpm.ks_contrib) * _xlpm.net_growth, _xlpm.result )} -> 12348.639 | Y3: {=_xlfn.LET( _xlpm.KS_rate, Dashboard!$Q$2 + 3%, _xlpm.ESCT_rate, 3%, _xlpm.W_HS, _xlfn.SWITCH(H3, "Recession", Dashboard!$Q$4, "Normal", Dashboard!$Q$8, "Boom", Dashboard!$Q$12 ), _xlpm.W_HR, _xlfn.SWITCH(H3, "Recession", Dashboard!$Q$5, "Normal", Dashboard!$Q$9, "Boom", Dashboard!$Q$13 ), _xlpm.W_SH, _xlfn.SWITCH(H3, "Recession", Dashboard!$Q$6, "Normal", Dashboard!$Q$10, "Boom", Dashboard!$Q$14 ), _xlpm.salary, C3, _xlpm.salary_with_employer, _xlpm.salary + _xlpm.salary * _xlpm.ESCT_rate, _xlpm.esct, _xlpm.salary * _xlpm.ESCT_rate * _xlfn.IFS( _xlpm.salary_with_employer <= 18720, 10.5%, _xlpm.salary_with_employer <= 64200, 17.5%, _xlpm.salary_with_employer <= 93720, 30%, _xlpm.salary_with_employer <= 216000, 33%, _xlpm.salary_with_employer > 216000, 39% ), _xlpm.ks_contrib, _xlpm.salary * _xlpm.KS_rate - _xlpm.esct + 521.43, _xlpm.return_rate, _xlpm.W_HS * I3 + _xlpm.W_HR * J3 + _xlpm.W_SH * K3, _xlpm.net_growth, (1 + _xlpm.return_rate) * (1 - 28%), _xlpm.prev_value, IF(ROW()=2, 0, X2), _xlpm.base, IF(ROW()=2, _xlpm.ks_contrib, _xlpm.prev_value + _xlpm.ks_contrib), _xlpm.current_value, _xlpm.base * _xlpm.net_growth, _xlpm.real_value, _xlpm.current_value * Q3, _xlpm.real_value )} -> 14625.646 | Z3: 72432.5 | AG3: 0.04
A4: 32 | B4: =VLOOKUP(t4_salaryGrowthevent!J4,t4_salaryGrowthevent!J:J,1,FALSE) -> 0.03475 | C4: =VLOOKUP(t4_salaryGrowthevent!B4,t4_salaryGrowthevent!B:B,1,FALSE) -> 74949.529 | D4: {=_xlfn.LET( _xlpm.taxable, C4, _xlpm.kiwisaver,C4*0.03, _xlpm.incomeTax, _xlfn.IFS( _xlpm.taxable <= 15600, _xlpm.taxable * 10.5%, AND(_xlpm.taxable > 15600, _xlpm.taxable <= 53500), (_xlpm.taxable - 15600) * 17.5% + 15600 * 10.5%, AND(_xlpm.taxable > 53500, _xlpm.taxable <= 78100), (_xlpm.taxable - 53500) * 30% + (53500 - 15600) * 17.5% + 15600 * 10.5%, AND(_xlpm.taxable > 78100, _xlpm.taxable <= 180000), (_xlpm.taxable - 78100) * 33% + (78100 - 53500) * 30% + (53500 - 15600) * 17.5% + 15600 * 10.5%, _xlpm.taxable > 180000, (_xlpm.taxable - 180000) * 39% + (180000 - 78100) * 33% + (78100 - 53500) * 30% + (53500 - 15600) * 17.5% + 15600 * 10.5% ), _xlpm.acc, C4 * 0.0167, _xlpm.taxable - _xlpm.incomeTax - _xlpm.acc - _xlpm.kiwisaver )} -> 56744.028 | E4: =6%*C4 -> 4496.9718 | F4: {=C4 * 3% * _xlfn.IFS( C4 + C4 * 3% <= 18720, 10.5%, C4 + C4 * 3% <= 64200, 17.5%, C4 + C4 * 3% <= 93720, 30%, C4 + C4 * 3% <= 216000, 33%, C4 + C4 * 3% > 216000, 39% )} -> 674.54576 | G4: =E4-F4+521.43 -> 4343.856 | H4: {=_xlfn.IFS( H3="Boom", CHOOSE(MATCH(RAND(), {0,0.67,1}, 1), "Normal", "Recession"), H3="Normal", CHOOSE(MATCH(RAND(), {0,0.18,0.82,1}, 1), "Boom", "Normal", "Recession"), H3="Recession", CHOOSE(MATCH(RAND(), {0,0.17,0.34,1}, 1), "Boom", "Normal", "Recession") )} -> Normal | I4: {=_xlfn.LET( _xlpm.ε, (_xlfn.BETA.INV(RAND(), 5, 5) - 0.5) * 2, _xlpm.Scenario,H4, _xlpm.pre_scenario,H3, _xlpm.μ, _xlfn.XLOOKUP("HarbourSafe", fundGrowth!$A$2:$A$4, INDEX(fundGrowth!$B$2:$J$4,0, MATCH(_xlpm.Scenario & " μ", fundGrowth!$B$1:$J$1, 0))), _xlpm.σ, _xlfn.XLOOKUP("HarbourSafe", fundGrowth!$A$2:$A$4, INDEX(fundGrowth!$B$2:$J$4,0, MATCH(_xlpm.Scenario & " σ", fundGrowth!$B$1:$J$1, 0))), _xlpm.ρ, _xlfn.XLOOKUP("HarbourSafe", fundGrowth!$A$2:$A$4, INDEX(fundGrowth!$B$2:$J$4,0, MATCH(_xlpm.Scenario & " ρ", fundGrowth!$B$1:$J$1, 0))), _xlpm.μ_prev, _xlfn.XLOOKUP("HarbourSafe", fundGrowth!$A$2:$A$4, INDEX(fundGrowth!$B$2:$J$4,0, MATCH(_xlpm.pre_scenario & " μ", fundGrowth!$B$1:$J$1, 0))), _xlpm.μ + _xlpm.ρ*(I3-_xlpm.μ_prev) + _xlpm.σ * _xlpm.ε )} -> 0.02923501 | J4: {=_xlfn.LET( _xlpm.ε, (_xlfn.BETA.INV(RAND(), 5, 5) - 0.5) * 2, _xlpm.Scenario,H4, _xlpm.pre_scenario,H3, _xlpm.μ, _xlfn.XLOOKUP("Horizon", fundGrowth!$A$2:$A$4, INDEX(fundGrowth!$B$2:$J$4,0, MATCH(_xlpm.Scenario & " μ", fundGrowth!$B$1:$J$1, 0))), _xlpm.σ, _xlfn.XLOOKUP("Horizon", fundGrowth!$A$2:$A$4, INDEX(fundGrowth!$B$2:$J$4,0, MATCH(_xlpm.Scenario & " σ", fundGrowth!$B$1:$J$1, 0))), _xlpm.ρ, _xlfn.XLOOKUP("Horizon", fundGrowth!$A$2:$A$4, INDEX(fundGrowth!$B$2:$J$4,0, MATCH(_xlpm.Scenario & " ρ", fundGrowth!$B$1:$J$1, 0))), _xlpm.μ_prev, _xlfn.XLOOKUP("Horizon", fundGrowth!$A$2:$A$4, INDEX(fundGrowth!$B$2:$J$4,0, MATCH(_xlpm.pre_scenario & " μ", fundGrowth!$B$1:$J$1, 0))), _xlpm.μ + _xlpm.ρ*(MAX(J3, -0.05)-_xlpm.μ_prev) + _xlpm.σ * _xlpm.ε )} -> 0.012295627 | K4: {=_xlfn.LET( _xlpm.ε, (_xlfn.BETA.INV(RAND(), 5, 5) - 0.5) * 2, _xlpm.Scenario,H4, _xlpm.pre_scenario,H3, _xlpm.μ, _xlfn.XLOOKUP("SkyHigh", fundGrowth!$A$2:$A$4, INDEX(fundGrowth!$B$2:$J$4,0, MATCH(_xlpm.Scenario & " μ", fundGrowth!$B$1:$J$1, 0))), _xlpm.σ, _xlfn.XLOOKUP("SkyHigh", fundGrowth!$A$2:$A$4, INDEX(fundGrowth!$B$2:$J$4,0, MATCH(_xlpm.Scenario & " σ", fundGrowth!$B$1:$J$1, 0))), _xlpm.ρ, _xlfn.XLOOKUP("SkyHigh", fundGrowth!$A$2:$A$4, INDEX(fundGrowth!$B$2:$J$4,0, MATCH(_xlpm.Scenario & " ρ", fundGrowth!$B$1:$J$1, 0))), _xlpm.μ_prev, _xlfn.XLOOKUP("SkyHigh", fundGrowth!$A$2:$A$4, INDEX(fundGrowth!$B$2:$J$4,0, MATCH(_xlpm.pre_scenario & " μ", fundGrowth!$B$1:$J$1, 0))), _xlpm.μ + _xlpm.ρ*(MAX(K3, -0.07)-_xlpm.μ_prev) + _xlpm.σ * _xlpm.ε )} -> 0.14404413 | L4: =0.4*I4+0.3*J4+0.3*K4 -> 0.058595932 | M4: =(M3+G4)*(1+L4)*(1-28%) -> 7566.2319 | N4: =M4*Q4 -> 7237.0006 | O4: =N4+D4*Q4 -> 61511.911 | P4: {=_xlfn.LET( _xlpm.state, H4, _xlpm.last, P3, _xlpm.μ, IF(RAND() < 0.001, 6% + 1.5% * _xlfn.NORM.S.INV(RAND()), _xlfn.BETA.INV(RAND(), 1.19, 1.22, 0.003, 0.04) ), _xlpm.ρ_min, _xlfn.IFS(_xlpm.state="Boom", 0.61, _xlpm.state="Normal", 0.34, _xlpm.state="Recession", 0.2), _xlpm.ρ_max, _xlfn.IFS(_xlpm.state="Boom", 0.8, _xlpm.state="Normal", 0.6, _xlpm.state="Recession", 0.33), _xlpm.α, _xlfn.IFS(_xlpm.state="Boom", 3, _xlpm.state="Normal", 2, _xlpm.state="Recession", 2), _xlpm.β, _xlfn.IFS(_xlpm.state="Boom", 2, _xlpm.state="Normal", 2, _xlpm.state="Recession", 3), _xlpm.ρ, _xlfn.BETA.INV(RAND(), _xlpm.α, _xlpm.β, _xlpm.ρ_min, _xlpm.ρ_max), _xlpm.ε, _xlfn.NORM.S.INV(RAND()), _xlpm.μ + _xlpm.ρ * (_xlpm.last - _xlpm.μ) + 0 * _xlpm.ε + MAX(0,_xlfn.IFS(A3=49,-_xlfn.NORM.INV(RAND(), 0.01, 0.005), A3=57,ABS(_xlfn.NORM.INV(RAND(), 0.02, 0.01)),TRUE,0)) )} -> 0.022824937 | Q4: =Q3/(1+P4) -> 0.95648676 | S4: {=_xlfn.LET( _xlpm.KS_rate, $V$2 + 3%, _xlpm.ESCT_rate, 3%, _xlpm.W_HS, $V$3, _xlpm.W_HR, $V$4, _xlpm.W_SH, $V$5, _xlpm.salary, C4, _xlpm.salary_with_employer, _xlpm.salary + _xlpm.salary * _xlpm.ESCT_rate, _xlpm.esct, _xlpm.salary * _xlpm.ESCT_rate * _xlfn.IFS( _xlpm.salary_with_employer <= 18720, 10.5%, _xlpm.salary_with_employer <= 64200, 17.5%, _xlpm.salary_with_employer <= 93720, 30%, _xlpm.salary_with_employer <= 216000, 33%, _xlpm.salary_with_employer > 216000, 39% ), _xlpm.ks_contrib, _xlpm.salary * _xlpm.KS_rate - _xlpm.esct + 521.43, _xlpm.return_rate, _xlpm.W_HS * I4 + _xlpm.W_HR * J4 + _xlpm.W_SH * K4, _xlpm.net_growth, (1 + _xlpm.return_rate) * (1 - 28%), _xlpm.prev_value, S3, _xlpm.result, (_xlpm.prev_value + _xlpm.ks_contrib) * _xlpm.net_growth, _xlpm.result )} -> 16673.855 | T4: {=_xlfn.LET( _xlpm.KS_rate, $V$2 + 3%, _xlpm.ESCT_rate, 3%, _xlpm.W_HS, $V$3, _xlpm.W_HR, $V$4, _xlpm.W_SH, $V$5, _xlpm.salary, C4, _xlpm.salary_with_employer, _xlpm.salary + _xlpm.salary * _xlpm.ESCT_rate, _xlpm.esct, _xlpm.salary * _xlpm.ESCT_rate * _xlfn.IFS( _xlpm.salary_with_employer <= 18720, 10.5%, _xlpm.salary_with_employer <= 64200, 17.5%, _xlpm.salary_with_employer <= 93720, 30%, _xlpm.salary_with_employer <= 216000, 33%, _xlpm.salary_with_employer > 216000, 39% ), _xlpm.ks_contrib, _xlpm.salary * _xlpm.KS_rate - _xlpm.esct + 521.43, _xlpm.return_rate, _xlpm.W_HS * I4 + _xlpm.W_HR * J4 + _xlpm.W_SH * K4, _xlpm.net_growth, (1 + _xlpm.return_rate) * (1 - 28%), _xlpm.prev_value, IF(ROW()=2, 0, S3), _xlpm.base, IF(ROW()=2, _xlpm.ks_contrib, _xlpm.prev_value + _xlpm.ks_contrib ), _xlpm.current_value, _xlpm.base * _xlpm.net_growth, _xlpm.real_value, _xlpm.current_value * Q4, _xlpm.real_value )} -> 15948.321 | U4: Horizon Rate | V4: 0.3 | X4: {=_xlfn.LET( _xlpm.KS_rate, Dashboard!$Q$2 + 3%, _xlpm.ESCT_rate, 3%, _xlpm.W_HS, _xlfn.SWITCH(H3, "Recession", Dashboard!$Q$4, "Normal", Dashboard!$Q$8, "Boom", Dashboard!$Q$12 ), _xlpm.W_HR, _xlfn.SWITCH(H3, "Recession", Dashboard!$Q$5, "Normal", Dashboard!$Q$9, "Boom", Dashboard!$Q$13 ), _xlpm.W_SH, _xlfn.SWITCH(H3, "Recession", Dashboard!$Q$6, "Normal", Dashboard!$Q$10, "Boom", Dashboard!$Q$14 ), _xlpm.salary, C4, _xlpm.salary_with_employer, _xlpm.salary + _xlpm.salary * _xlpm.ESCT_rate, _xlpm.esct, _xlpm.salary * _xlpm.ESCT_rate * _xlfn.IFS( _xlpm.salary_with_employer <= 18720, 10.5%, _xlpm.salary_with_employer <= 64200, 17.5%, _xlpm.salary_with_employer <= 93720, 30%, _xlpm.salary_with_employer <= 216000, 33%, _xlpm.salary_with_employer > 216000, 39% ), _xlpm.ks_contrib, _xlpm.salary * _xlpm.KS_rate - _xlpm.esct + 521.43, _xlpm.return_rate, _xlpm.W_HS * I4 + _xlpm.W_HR * J4 + _xlpm.W_SH * K4, _xlpm.net_growth, (1 + _xlpm.return_rate) * (1 - 28%), _xlpm.prev_value, S3, _xlpm.result, (_xlpm.prev_value + _xlpm.ks_contrib) * _xlpm.net_growth, _xlpm.result )} -> 18019.742 | Y4: {=_xlfn.LET( _xlpm.KS_rate, Dashboard!$Q$2 + 3%, _xlpm.ESCT_rate, 3%, _xlpm.W_HS, _xlfn.SWITCH(H4, "Recession", Dashboard!$Q$4, "Normal", Dashboard!$Q$8, "Boom", Dashboard!$Q$12 ), _xlpm.W_HR, _xlfn.SWITCH(H4, "Recession", Dashboard!$Q$5, "Normal", Dashboard!$Q$9, "Boom", Dashboard!$Q$13 ), _xlpm.W_SH, _xlfn.SWITCH(H4, "Recession", Dashboard!$Q$6, "Normal", Dashboard!$Q$10, "Boom", Dashboard!$Q$14 ), _xlpm.salary, C4, _xlpm.salary_with_employer, _xlpm.salary + _xlpm.salary * _xlpm.ESCT_rate, _xlpm.esct, _xlpm.salary * _xlpm.ESCT_rate * _xlfn.IFS( _xlpm.salary_with_employer <= 18720, 10.5%, _xlpm.salary_with_employer <= 64200, 17.5%, _xlpm.salary_with_employer <= 93720, 30%, _xlpm.salary_with_employer <= 216000, 33%, _xlpm.salary_with_employer > 216000, 39% ), _xlpm.ks_contrib, _xlpm.salary * _xlpm.KS_rate - _xlpm.esct + 521.43, _xlpm.return_rate, _xlpm.W_HS * I4 + _xlpm.W_HR * J4 + _xlpm.W_SH * K4, _xlpm.net_growth, (1 + _xlpm.return_rate) * (1 - 28%), _xlpm.prev_value, IF(ROW()=2, 0, X3), _xlpm.base, IF(ROW()=2, _xlpm.ks_contrib, _xlpm.prev_value + _xlpm.ks_contrib), _xlpm.current_value, _xlpm.base * _xlpm.net_growth, _xlpm.real_value, _xlpm.current_value * Q4, _xlpm.real_value )} -> 16289.761 | Z4: 74949.529 | AG4: 0.06
A5: 33 | B5: =VLOOKUP(t4_salaryGrowthevent!J5,t4_salaryGrowthevent!J:J,1,FALSE) -> 0.03475 | C5: =VLOOKUP(t4_salaryGrowthevent!B5,t4_salaryGrowthevent!B:B,1,FALSE) -> 77554.026 | D5: {=_xlfn.LET( _xlpm.taxable, C5, _xlpm.kiwisaver,C5*0.03, _xlpm.incomeTax, _xlfn.IFS( _xlpm.taxable <= 15600, _xlpm.taxable * 10.5%, AND(_xlpm.taxable > 15600, _xlpm.taxable <= 53500), (_xlpm.taxable - 15600) * 17.5% + 15600 * 10.5%, AND(_xlpm.taxable > 53500, _xlpm.taxable <= 78100), (_xlpm.taxable - 53500) * 30% + (53500 - 15600) * 17.5% + 15600 * 10.5%, AND(_xlpm.taxable > 78100, _xlpm.taxable <= 180000), (_xlpm.taxable - 78100) * 33% + (78100 - 53500) * 30% + (53500 - 15600) * 17.5% + 15600 * 10.5%, _xlpm.taxable > 180000, (_xlpm.taxable - 180000) * 39% + (180000 - 78100) * 33% + (78100 - 53500) * 30% + (53500 - 15600) * 17.5% + 15600 * 10.5% ), _xlpm.acc, C5 * 0.0167, _xlpm.taxable - _xlpm.incomeTax - _xlpm.acc - _xlpm.kiwisaver )} -> 58445.545 | E5: =6%*C5 -> 4653.2415 | F5: {=C5 * 3% * _xlfn.IFS( C5 + C5 * 3% <= 18720, 10.5%, C5 + C5 * 3% <= 64200, 17.5%, C5 + C5 * 3% <= 93720, 30%, C5 + C5 * 3% <= 216000, 33%, C5 + C5 * 3% > 216000, 39% )} -> 697.98623 | G5: =E5-F5+521.43 -> 4476.6853 | H5: {=_xlfn.IFS( H4="Boom", CHOOSE(MATCH(RAND(), {0,0.67,1}, 1), "Normal", "Recession"), H4="Normal", CHOOSE(MATCH(RAND(), {0,0.18,0.82,1}, 1), "Boom", "Normal", "Recession"), H4="Recession", CHOOSE(MATCH(RAND(), {0,0.17,0.34,1}, 1), "Boom", "Normal", "Recession") )} -> Normal | I5: {=_xlfn.LET( _xlpm.ε, (_xlfn.BETA.INV(RAND(), 5, 5) - 0.5) * 2, _xlpm.Scenario,H5, _xlpm.pre_scenario,H4, _xlpm.μ, _xlfn.XLOOKUP("HarbourSafe", fundGrowth!$A$2:$A$4, INDEX(fundGrowth!$B$2:$J$4,0, MATCH(_xlpm.Scenario & " μ", fundGrowth!$B$1:$J$1, 0))), _xlpm.σ, _xlfn.XLOOKUP("HarbourSafe", fundGrowth!$A$2:$A$4, INDEX(fundGrowth!$B$2:$J$4,0, MATCH(_xlpm.Scenario & " σ", fundGrowth!$B$1:$J$1, 0))), _xlpm.ρ, _xlfn.XLOOKUP("HarbourSafe", fundGrowth!$A$2:$A$4, INDEX(fundGrowth!$B$2:$J$4,0, MATCH(_xlpm.Scenario & " ρ", fundGrowth!$B$1:$J$1, 0))), _xlpm.μ_prev, _xlfn.XLOOKUP("HarbourSafe", fundGrowth!$A$2:$A$4, INDEX(fundGrowth!$B$2:$J$4,0, MATCH(_xlpm.pre_scenario & " μ", fundGrowth!$B$1:$J$1, 0))), _xlpm.μ + _xlpm.ρ*(I4-_xlpm.μ_prev) + _xlpm.σ * _xlpm.ε )} -> 0.042967787 | J5: {=_xlfn.LET( _xlpm.ε, (_xlfn.BETA.INV(RAND(), 5, 5) - 0.5) * 2, _xlpm.Scenario,H5, _xlpm.pre_scenario,H4, _xlpm.μ, _xlfn.XLOOKUP("Horizon", fundGrowth!$A$2:$A$4, INDEX(fundGrowth!$B$2:$J$4,0, MATCH(_xlpm.Scenario & " μ", fundGrowth!$B$1:$J$1, 0))), _xlpm.σ, _xlfn.XLOOKUP("Horizon", fundGrowth!$A$2:$A$4, INDEX(fundGrowth!$B$2:$J$4,0, MATCH(_xlpm.Scenario & " σ", fundGrowth!$B$1:$J$1, 0))), _xlpm.ρ, _xlfn.XLOOKUP("Horizon", fundGrowth!$A$2:$A$4, INDEX(fundGrowth!$B$2:$J$4,0, MATCH(_xlpm.Scenario & " ρ", fundGrowth!$B$1:$J$1, 0))), _xlpm.μ_prev, _xlfn.XLOOKUP("Horizon", fundGrowth!$A$2:$A$4, INDEX(fundGrowth!$B$2:$J$4,0, MATCH(_xlpm.pre_scenario & " μ", fundGrowth!$B$1:$J$1, 0))), _xlpm.μ + _xlpm.ρ*(MAX(J4, -0.05)-_xlpm.μ_prev) + _xlpm.σ * _xlpm.ε )} -> 0.0092928476 | K5: {=_xlfn.LET( _xlpm.ε, (_xlfn.BETA.INV(RAND(), 5, 5) - 0.5) * 2, _xlpm.Scenario,H5, _xlpm.pre_scenario,H4, _xlpm.μ, _xlfn.XLOOKUP("SkyHigh", fundGrowth!$A$2:$A$4, INDEX(fundGrowth!$B$2:$J$4,0, MATCH(_xlpm.Scenario & " μ", fundGrowth!$B$1:$J$1, 0))), _xlpm.σ, _xlfn.XLOOKUP("SkyHigh", fundGrowth!$A$2:$A$4, INDEX(fundGrowth!$B$2:$J$4,0, MATCH(_xlpm.Scenario & " σ", fundGrowth!$B$1:$J$1, 0))), _xlpm.ρ, _xlfn.XLOOKUP("SkyHigh", fundGrowth!$A$2:$A$4, INDEX(fundGrowth!$B$2:$J$4,0, MATCH(_xlpm.Scenario & " ρ", fundGrowth!$B$1:$J$1, 0))), _xlpm.μ_prev, _xlfn.XLOOKUP("SkyHigh", fundGrowth!$A$2:$A$4, INDEX(fundGrowth!$B$2:$J$4,0, MATCH(_xlpm.pre_scenario & " μ", fundGrowth!$B$1:$J$1, 0))), _xlpm.μ + _xlpm.ρ*(MAX(K4, -0.07)-_xlpm.μ_prev) + _xlpm.σ * _xlpm.ε )} -> 0.17686776 | L5: =0.4*I5+0.3*J5+0.3*K5 -> 0.073035296 | M5: =(M4+G5)*(1+L5)*(1-28%) -> 9304.1821 | N5: =M5*Q5 -> 8722.949 | O5: =N5+D5*Q5 -> 63517.395 | P5: {=_xlfn.LET( _xlpm.state, H5, _xlpm.last, P4, _xlpm.μ, IF(RAND() < 0.001, 6% + 1.5% * _xlfn.NORM.S.INV(RAND()), _xlfn.BETA.INV(RAND(), 1.19, 1.22, 0.003, 0.04) ), _xlpm.ρ_min, _xlfn.IFS(_xlpm.state="Boom", 0.61, _xlpm.state="Normal", 0.34, _xlpm.state="Recession", 0.2), _xlpm.ρ_max, _xlfn.IFS(_xlpm.state="Boom", 0.8, _xlpm.state="Normal", 0.6, _xlpm.state="Recession", 0.33), _xlpm.α, _xlfn.IFS(_xlpm.state="Boom", 3, _xlpm.state="Normal", 2, _xlpm.state="Recession", 2), _xlpm.β, _xlfn.IFS(_xlpm.state="Boom", 2, _xlpm.state="Normal", 2, _xlpm.state="Recession", 3), _xlpm.ρ, _xlfn.BETA.INV(RAND(), _xlpm.α, _xlpm.β, _xlpm.ρ_min, _xlpm.ρ_max), _xlpm.ε, _xlfn.NORM.S.INV(RAND()), _xlpm.μ + _xlpm.ρ * (_xlpm.last - _xlpm.μ) + 0 * _xlpm.ε + MAX(0,_xlfn.IFS(A4=49,-_xlfn.NORM.INV(RAND(), 0.01, 0.005), A4=57,ABS(_xlfn.NORM.INV(RAND(), 0.02, 0.01)),TRUE,0)) )} -> 0.02022 | Q5: =Q4/(1+P5) -> 0.9375299 | S5: {=_xlfn.LET( _xlpm.KS_rate, $V$2 + 3%, _xlpm.ESCT_rate, 3%, _xlpm.W_HS, $V$3, _xlpm.W_HR, $V$4, _xlpm.W_SH, $V$5, _xlpm.salary, C5, _xlpm.salary_with_employer, _xlpm.salary + _xlpm.salary * _xlpm.ESCT_rate, _xlpm.esct, _xlpm.salary * _xlpm.ESCT_rate * _xlfn.IFS( _xlpm.salary_with_employer <= 18720, 10.5%, _xlpm.salary_with_employer <= 64200, 17.5%, _xlpm.salary_with_employer <= 93720, 30%, _xlpm.salary_with_employer <= 216000, 33%, _xlpm.salary_with_employer > 216000, 39% ), _xlpm.ks_contrib, _xlpm.salary * _xlpm.KS_rate - _xlpm.esct + 521.43, _xlpm.return_rate, _xlpm.W_HS * I5 + _xlpm.W_HR * J5 + _xlpm.W_SH * K5, _xlpm.net_growth, (1 + _xlpm.return_rate) * (1 - 28%), _xlpm.prev_value, S4, _xlpm.result, (_xlpm.prev_value + _xlpm.ks_contrib) * _xlpm.net_growth, _xlpm.result )} -> 20534.796 | T5: {=_xlfn.LET( _xlpm.KS_rate, $V$2 + 3%, _xlpm.ESCT_rate, 3%, _xlpm.W_HS, $V$3, _xlpm.W_HR, $V$4, _xlpm.W_SH, $V$5, _xlpm.salary, C5, _xlpm.salary_with_employer, _xlpm.salary + _xlpm.salary * _xlpm.ESCT_rate, _xlpm.esct, _xlpm.salary * _xlpm.ESCT_rate * _xlfn.IFS( _xlpm.salary_with_employer <= 18720, 10.5%, _xlpm.salary_with_employer <= 64200, 17.5%, _xlpm.salary_with_employer <= 93720, 30%, _xlpm.salary_with_employer <= 216000, 33%, _xlpm.salary_with_employer > 216000, 39% ), _xlpm.ks_contrib, _xlpm.salary * _xlpm.KS_rate - _xlpm.esct + 521.43, _xlpm.return_rate, _xlpm.W_HS * I5 + _xlpm.W_HR * J5 + _xlpm.W_SH * K5, _xlpm.net_growth, (1 + _xlpm.return_rate) * (1 - 28%), _xlpm.prev_value, IF(ROW()=2, 0, S4), _xlpm.base, IF(ROW()=2, _xlpm.ks_contrib, _xlpm.prev_value + _xlpm.ks_contrib ), _xlpm.current_value, _xlpm.base * _xlpm.net_growth, _xlpm.real_value, _xlpm.current_value * Q5, _xlpm.real_value )} -> 19251.986 | U5: SkyHigh Rate | V5: 0.3 | X5: {=_xlfn.LET( _xlpm.KS_rate, Dashboard!$Q$2 + 3%, _xlpm.ESCT_rate, 3%, _xlpm.W_HS, _xlfn.SWITCH(H4, "Recession", Dashboard!$Q$4, "Normal", Dashboard!$Q$8, "Boom", Dashboard!$Q$12 ), _xlpm.W_HR, _xlfn.SWITCH(H4, "Recession", Dashboard!$Q$5, "Normal", Dashboard!$Q$9, "Boom", Dashboard!$Q$13 ), _xlpm.W_SH, _xlfn.SWITCH(H4, "Recession", Dashboard!$Q$6, "Normal", Dashboard!$Q$10, "Boom", Dashboard!$Q$14 ), _xlpm.salary, C5, _xlpm.salary_with_employer, _xlpm.salary + _xlpm.salary * _xlpm.ESCT_rate, _xlpm.esct, _xlpm.salary * _xlpm.ESCT_rate * _xlfn.IFS( _xlpm.salary_with_employer <= 18720, 10.5%, _xlpm.salary_with_employer <= 64200, 17.5%, _xlpm.salary_with_employer <= 93720, 30%, _xlpm.salary_with_employer <= 216000, 33%, _xlpm.salary_with_employer > 216000, 39% ), _xlpm.ks_contrib, _xlpm.salary * _xlpm.KS_rate - _xlpm.esct + 521.43, _xlpm.return_rate, _xlpm.W_HS * I5 + _xlpm.W_HR * J5 + _xlpm.W_SH * K5, _xlpm.net_growth, (1 + _xlpm.return_rate) * (1 - 28%), _xlpm.prev_value, S4, _xlpm.result, (_xlpm.prev_value + _xlpm.ks_contrib) * _xlpm.net_growth, _xlpm.result )} -> 20918.4 | Y5: {=_xlfn.LET( _xlpm.KS_rate, Dashboard!$Q$2 + 3%, _xlpm.ESCT_rate, 3%, _xlpm.W_HS, _xlfn.SWITCH(H5, "Recession", Dashboard!$Q$4, "Normal", Dashboard!$Q$8, "Boom", Dashboard!$Q$12 ), _xlpm.W_HR, _xlfn.SWITCH(H5, "Recession", Dashboard!$Q$5, "Normal", Dashboard!$Q$9, "Boom", Dashboard!$Q$13 ), _xlpm.W_SH, _xlfn.SWITCH(H5, "Recession", Dashboard!$Q$6, "Normal", Dashboard!$Q$10, "Boom", Dashboard!$Q$14 ), _xlpm.salary, C5, _xlpm.salary_with_employer, _xlpm.salary + _xlpm.salary * _xlpm.ESCT_rate, _xlpm.esct, _xlpm.salary * _xlpm.ESCT_rate * _xlfn.IFS( _xlpm.salary_with_employer <= 18720, 10.5%, _xlpm.salary_with_employer <= 64200, 17.5%, _xlpm.salary_with_employer <= 93720, 30%, _xlpm.salary_with_employer <= 216000, 33%, _xlpm.salary_with_employer > 216000, 39% ), _xlpm.ks_contrib, _xlpm.salary * _xlpm.KS_rate - _xlpm.esct + 521.43, _xlpm.return_rate, _xlpm.W_HS * I5 + _xlpm.W_HR * J5 + _xlpm.W_SH * K5, _xlpm.net_growth, (1 + _xlpm.return_rate) * (1 - 28%), _xlpm.prev_value, IF(ROW()=2, 0, X4), _xlpm.base, IF(ROW()=2, _xlpm.ks_contrib, _xlpm.prev_value + _xlpm.ks_contrib), _xlpm.current_value, _xlpm.base * _xlpm.net_growth, _xlpm.real_value, _xlpm.current_value * Q5, _xlpm.real_value )} -> 20604.692 | Z5: 77554.026 | AG5: 0.08
A6: 34 | B6: =VLOOKUP(t4_salaryGrowthevent!J6,t4_salaryGrowthevent!J:J,1,FALSE) -> 0.03475 | C6: =VLOOKUP(t4_salaryGrowthevent!B6,t4_salaryGrowthevent!B:B,1,FALSE) -> 80249.028 | D6: {=_xlfn.LET( _xlpm.taxable, C6, _xlpm.kiwisaver,C6*0.03, _xlpm.incomeTax, _xlfn.IFS( _xlpm.taxable <= 15600, _xlpm.taxable * 10.5%, AND(_xlpm.taxable > 15600, _xlpm.taxable <= 53500), (_xlpm.taxable - 15600) * 17.5% + 15600 * 10.5%, AND(_xlpm.taxable > 53500, _xlpm.taxable <= 78100), (_xlpm.taxable - 53500) * 30% + (53500 - 15600) * 17.5% + 15600 * 10.5%, AND(_xlpm.taxable > 78100, _xlpm.taxable <= 180000), (_xlpm.taxable - 78100) * 33% + (78100 - 53500) * 30% + (53500 - 15600) * 17.5% + 15600 * 10.5%, _xlpm.taxable > 180000, (_xlpm.taxable - 180000) * 39% + (180000 - 78100) * 33% + (78100 - 53500) * 30% + (53500 - 15600) * 17.5% + 15600 * 10.5% ), _xlpm.acc, C6 * 0.0167, _xlpm.taxable - _xlpm.incomeTax - _xlpm.acc - _xlpm.kiwisaver )} -> 60141.719 | E6: =6%*C6 -> 4814.9417 | F6: {=C6 * 3% * _xlfn.IFS( C6 + C6 * 3% <= 18720, 10.5%, C6 + C6 * 3% <= 64200, 17.5%, C6 + C6 * 3% <= 93720, 30%, C6 + C6 * 3% <= 216000, 33%, C6 + C6 * 3% > 216000, 39% )} -> 722.24125 | G6: =E6-F6+521.43 -> 4614.1304 | H6: {=_xlfn.IFS( H5="Boom", CHOOSE(MATCH(RAND(), {0,0.67,1}, 1), "Normal", "Recession"), H5="Normal", CHOOSE(MATCH(RAND(), {0,0.18,0.82,1}, 1), "Boom", "Normal", "Recession"), H5="Recession", CHOOSE(MATCH(RAND(), {0,0.17,0.34,1}, 1), "Boom", "Normal", "Recession") )} -> Normal | I6: {=_xlfn.LET( _xlpm.ε, (_xlfn.BETA.INV(RAND(), 5, 5) - 0.5) * 2, _xlpm.Scenario,H6, _xlpm.pre_scenario,H5, _xlpm.μ, _xlfn.XLOOKUP("HarbourSafe", fundGrowth!$A$2:$A$4, INDEX(fundGrowth!$B$2:$J$4,0, MATCH(_xlpm.Scenario & " μ", fundGrowth!$B$1:$J$1, 0))), _xlpm.σ, _xlfn.XLOOKUP("HarbourSafe", fundGrowth!$A$2:$A$4, INDEX(fundGrowth!$B$2:$J$4,0, MATCH(_xlpm.Scenario & " σ", fundGrowth!$B$1:$J$1, 0))), _xlpm.ρ, _xlfn.XLOOKUP("HarbourSafe", fundGrowth!$A$2:$A$4, INDEX(fundGrowth!$B$2:$J$4,0, MATCH(_xlpm.Scenario & " ρ", fundGrowth!$B$1:$J$1, 0))), _xlpm.μ_prev, _xlfn.XLOOKUP("HarbourSafe", fundGrowth!$A$2:$A$4, INDEX(fundGrowth!$B$2:$J$4,0, MATCH(_xlpm.pre_scenario & " μ", fundGrowth!$B$1:$J$1, 0))), _xlpm.μ + _xlpm.ρ*(I5-_xlpm.μ_prev) + _xlpm.σ * _xlpm.ε )} -> 0.068419423 | J6: {=_xlfn.LET( _xlpm.ε, (_xlfn.BETA.INV(RAND(), 5, 5) - 0.5) * 2, _xlpm.Scenario,H6, _xlpm.pre_scenario,H5, _xlpm.μ, _xlfn.XLOOKUP("Horizon", fundGrowth!$A$2:$A$4, INDEX(fundGrowth!$B$2:$J$4,0, MATCH(_xlpm.Scenario & " μ", fundGrowth!$B$1:$J$1, 0))), _xlpm.σ, _xlfn.XLOOKUP("Horizon", fundGrowth!$A$2:$A$4, INDEX(fundGrowth!$B$2:$J$4,0, MATCH(_xlpm.Scenario & " σ", fundGrowth!$B$1:$J$1, 0))), _xlpm.ρ, _xlfn.XLOOKUP("Horizon", fundGrowth!$A$2:$A$4, INDEX(fundGrowth!$B$2:$J$4,0, MATCH(_xlpm.Scenario & " ρ", fundGrowth!$B$1:$J$1, 0))), _xlpm.μ_prev, _xlfn.XLOOKUP("Horizon", fundGrowth!$A$2:$A$4, INDEX(fundGrowth!$B$2:$J$4,0, MATCH(_xlpm.pre_scenario & " μ", fundGrowth!$B$1:$J$1, 0))), _xlpm.μ + _xlpm.ρ*(MAX(J5, -0.05)-_xlpm.μ_prev) + _xlpm.σ * _xlpm.ε )} -> 0.015874884 | K6: {=_xlfn.LET( _xlpm.ε, (_xlfn.BETA.INV(RAND(), 5, 5) - 0.5) * 2, _xlpm.Scenario,H6, _xlpm.pre_scenario,H5, _xlpm.μ, _xlfn.XLOOKUP("SkyHigh", fundGrowth!$A$2:$A$4, INDEX(fundGrowth!$B$2:$J$4,0, MATCH(_xlpm.Scenario & " μ", fundGrowth!$B$1:$J$1, 0))), _xlpm.σ, _xlfn.XLOOKUP("SkyHigh", fundGrowth!$A$2:$A$4, INDEX(fundGrowth!$B$2:$J$4,0, MATCH(_xlpm.Scenario & " σ", fundGrowth!$B$1:$J$1, 0))), _xlpm.ρ, _xlfn.XLOOKUP("SkyHigh", fundGrowth!$A$2:$A$4, INDEX(fundGrowth!$B$2:$J$4,0, MATCH(_xlpm.Scenario & " ρ", fundGrowth!$B$1:$J$1, 0))), _xlpm.μ_prev, _xlfn.XLOOKUP("SkyHigh", fundGrowth!$A$2:$A$4, INDEX(fundGrowth!$B$2:$J$4,0, MATCH(_xlpm.pre_scenario & " μ", fundGrowth!$B$1:$J$1, 0))), _xlpm.μ + _xlpm.ρ*(MAX(K5, -0.07)-_xlpm.μ_prev) + _xlpm.σ * _xlpm.ε )} -> 0.081035543 | L6: =0.4*I6+0.3*J6+0.3*K6 -> 0.056440897 | M6: =(M5+G6)*(1+L6)*(1-28%) -> 10586.79 | N6: =M6*Q6 -> 9775.5343 | O6: =N6+D6*Q6 -> 65308.652 | P6: {=_xlfn.LET( _xlpm.state, H6, _xlpm.last, P5, _xlpm.μ, IF(RAND() < 0.001, 6% + 1.5% * _xlfn.NORM.S.INV(RAND()), _xlfn.BETA.INV(RAND(), 1.19, 1.22, 0.003, 0.04) ), _xlpm.ρ_min, _xlfn.IFS(_xlpm.state="Boom", 0.61, _xlpm.state="Normal", 0.34, _xlpm.state="Recession", 0.2), _xlpm.ρ_max, _xlfn.IFS(_xlpm.state="Boom", 0.8, _xlpm.state="Normal", 0.6, _xlpm.state="Recession", 0.33), _xlpm.α, _xlfn.IFS(_xlpm.state="Boom", 3, _xlpm.state="Normal", 2, _xlpm.state="Recession", 2), _xlpm.β, _xlfn.IFS(_xlpm.state="Boom", 2, _xlpm.state="Normal", 2, _xlpm.state="Recession", 3), _xlpm.ρ, _xlfn.BETA.INV(RAND(), _xlpm.α, _xlpm.β, _xlpm.ρ_min, _xlpm.ρ_max), _xlpm.ε, _xlfn.NORM.S.INV(RAND()), _xlpm.μ + _xlpm.ρ * (_xlpm.last - _xlpm.μ) + 0 * _xlpm.ε + MAX(0,_xlfn.IFS(A5=49,-_xlfn.NORM.INV(RAND(), 0.01, 0.005), A5=57,ABS(_xlfn.NORM.INV(RAND(), 0.02, 0.01)),TRUE,0)) )} -> 0.015333959 | Q6: =Q5/(1+P6) -> 0.92337097 | S6: {=_xlfn.LET( _xlpm.KS_rate, $V$2 + 3%, _xlpm.ESCT_rate, 3%, _xlpm.W_HS, $V$3, _xlpm.W_HR, $V$4, _xlpm.W_SH, $V$5, _xlpm.salary, C6, _xlpm.salary_with_employer, _xlpm.salary + _xlpm.salary * _xlpm.ESCT_rate, _xlpm.esct, _xlpm.salary * _xlpm.ESCT_rate * _xlfn.IFS( _xlpm.salary_with_employer <= 18720, 10.5%, _xlpm.salary_with_employer <= 64200, 17.5%, _xlpm.salary_with_employer <= 93720, 30%, _xlpm.salary_with_employer <= 216000, 33%, _xlpm.salary_with_employer > 216000, 39% ), _xlpm.ks_contrib, _xlpm.salary * _xlpm.KS_rate - _xlpm.esct + 521.43, _xlpm.return_rate, _xlpm.W_HS * I6 + _xlpm.W_HR * J6 + _xlpm.W_SH * K6, _xlpm.net_growth, (1 + _xlpm.return_rate) * (1 - 28%), _xlpm.prev_value, S5, _xlpm.result, (_xlpm.prev_value + _xlpm.ks_contrib) * _xlpm.net_growth, _xlpm.result )} -> 23402.045 | T6: {=_xlfn.LET( _xlpm.KS_rate, $V$2 + 3%, _xlpm.ESCT_rate, 3%, _xlpm.W_HS, $V$3, _xlpm.W_HR, $V$4, _xlpm.W_SH, $V$5, _xlpm.salary, C6, _xlpm.salary_with_employer, _xlpm.salary + _xlpm.salary * _xlpm.ESCT_rate, _xlpm.esct, _xlpm.salary * _xlpm.ESCT_rate * _xlfn.IFS( _xlpm.salary_with_employer <= 18720, 10.5%, _xlpm.salary_with_employer <= 64200, 17.5%, _xlpm.salary_with_employer <= 93720, 30%, _xlpm.salary_with_employer <= 216000, 33%, _xlpm.salary_with_employer > 216000, 39% ), _xlpm.ks_contrib, _xlpm.salary * _xlpm.KS_rate - _xlpm.esct + 521.43, _xlpm.return_rate, _xlpm.W_HS * I6 + _xlpm.W_HR * J6 + _xlpm.W_SH * K6, _xlpm.net_growth, (1 + _xlpm.return_rate) * (1 - 28%), _xlpm.prev_value, IF(ROW()=2, 0, S5), _xlpm.base, IF(ROW()=2, _xlpm.ks_contrib, _xlpm.prev_value + _xlpm.ks_contrib ), _xlpm.current_value, _xlpm.base * _xlpm.net_growth, _xlpm.real_value, _xlpm.current_value * Q6, _xlpm.real_value )} -> 21608.769 | X6: {=_xlfn.LET( _xlpm.KS_rate, Dashboard!$Q$2 + 3%, _xlpm.ESCT_rate, 3%, _xlpm.W_HS, _xlfn.SWITCH(H5, "Recession", Dashboard!$Q$4, "Normal", Dashboard!$Q$8, "Boom", Dashboard!$Q$12 ), _xlpm.W_HR, _xlfn.SWITCH(H5, "Recession", Dashboard!$Q$5, "Normal", Dashboard!$Q$9, "Boom", Dashboard!$Q$13 ), _xlpm.W_SH, _xlfn.SWITCH(H5, "Recession", Dashboard!$Q$6, "Normal", Dashboard!$Q$10, "Boom", Dashboard!$Q$14 ), _xlpm.salary, C6, _xlpm.salary_with_employer, _xlpm.salary + _xlpm.salary * _xlpm.ESCT_rate, _xlpm.esct, _xlpm.salary * _xlpm.ESCT_rate * _xlfn.IFS( _xlpm.salary_with_employer <= 18720, 10.5%, _xlpm.salary_with_employer <= 64200, 17.5%, _xlpm.salary_with_employer <= 93720, 30%, _xlpm.salary_with_employer <= 216000, 33%, _xlpm.salary_with_employer > 216000, 39% ), _xlpm.ks_contrib, _xlpm.salary * _xlpm.KS_rate - _xlpm.esct + 521.43, _xlpm.return_rate, _xlpm.W_HS * I6 + _xlpm.W_HR * J6 + _xlpm.W_SH * K6, _xlpm.net_growth, (1 + _xlpm.return_rate) * (1 - 28%), _xlpm.prev_value, S5, _xlpm.result, (_xlpm.prev_value + _xlpm.ks_contrib) * _xlpm.net_growth, _xlpm.result )} -> 23225.147 | Y6: {=_xlfn.LET( _xlpm.KS_rate, Dashboard!$Q$2 + 3%, _xlpm.ESCT_rate, 3%, _xlpm.W_HS, _xlfn.SWITCH(H6, "Recession", Dashboard!$Q$4, "Normal", Dashboard!$Q$8, "Boom", Dashboard!$Q$12 ), _xlpm.W_HR, _xlfn.SWITCH(H6, "Recession", Dashboard!$Q$5, "Normal", Dashboard!$Q$9, "Boom", Dashboard!$Q$13 ), _xlpm.W_SH, _xlfn.SWITCH(H6, "Recession", Dashboard!$Q$6, "Normal", Dashboard!$Q$10, "Boom", Dashboard!$Q$14 ), _xlpm.salary, C6, _xlpm.salary_with_employer, _xlpm.salary + _xlpm.salary * _xlpm.ESCT_rate, _xlpm.esct, _xlpm.salary * _xlpm.ESCT_rate * _xlfn.IFS( _xlpm.salary_with_employer <= 18720, 10.5%, _xlpm.salary_with_employer <= 64200, 17.5%, _xlpm.salary_with_employer <= 93720, 30%, _xlpm.salary_with_employer <= 216000, 33%, _xlpm.salary_with_employer > 216000, 39% ), _xlpm.ks_contrib, _xlpm.salary * _xlpm.KS_rate - _xlpm.esct + 521.43, _xlpm.return_rate, _xlpm.W_HS * I6 + _xlpm.W_HR * J6 + _xlpm.W_SH * K6, _xlpm.net_growth, (1 + _xlpm.return_rate) * (1 - 28%), _xlpm.prev_value, IF(ROW()=2, 0, X5), _xlpm.base, IF(ROW()=2, _xlpm.ks_contrib, _xlpm.prev_value + _xlpm.ks_contrib), _xlpm.current_value, _xlpm.base * _xlpm.net_growth, _xlpm.real_value, _xlpm.current_value * Q6, _xlpm.real_value )} -> 21712.815 | Z6: 80249.028 | AG6: 0.1
